Workbook

Sheet BOM
A1: BOM: ESP32 Hue/RGB-lamptester (Light-Colour-Led-Testbench)
A2: Prijzen in € incl. 21% btw, gecontroleerd op 2026-10-26. Deel A is aan te kopen, deel B is al in bezit of komt van school. Gele cellen mag je aanpassen. Oranje prijs = schatting. Onderaan staan alternatieven voor de licht- en kleursensor (niet meegeteld).
A4: Ref | B4: Onderdeel | C4: Korte beschrijving | D4: Waarom nodig en waarom deze keuze | E4: Link naar webshop | F4: Aantal nodig | G4: Hergebruik (in bezit) | H4: Reserve (stuks) | I4: Te kopen | J4: Prijs per stuk incl. btw | K4: Totaal incl. btw | L4: Leverancier | M4: Voorraad en levertijd | N4: Jouw originele lijst | O4: Prijsstatus | P4: Opmerking (hergebruik / beschikbaarheid)
A5: A. Aan te kopen
A6: R01 | B6: AS7341 kleur-/spectraalsensor | C6: 10-kanaals spectraalsensor (Adafruit ADA-4698), I2C 0x39. Meet kleur en spectrum van de lamp. | D6: Nodig om de kleur van de Hue-lamp objectief te meten. De AS7341 meet 8 zichtbare banden plus NIR en clear, dat is nauwkeuriger dan een gewone RGB-sensor. Gekozen boven goedkopere sensoren (zie onderaan) voor een betere kleurcontrole. Geen reserve: duur; alternatieve webshops staan op het tabblad Alternatieven. | E6: Koop hier | F6: 1 | G6: 0 | H6: 0 | I6: =IF(F6>G6,F6-G6+H6,0) -> 1 | J6: =ROUND(15.29*(1+Aannames!$B$4),2) -> 18.5 | K6: =I6*J6 -> 18.5 | L6: Kiwi Electronics | M6: Kiwi toont € 15,29 excl. btw (= € 18,50 incl.). Voorraad niet zichtbaar; Adafruit.com meldt 'out of stock'. Bevestigen in winkelwagen. | N6: Ja (in je lijst) | O6: Geverifieerd
A7: R02 | B7: BH1750 luxsensor (Adafruit, STEMMA QT) | C7: Digitale lichtsensor in lux (BH1750-chip), I2C 0x23, 3-5 V, op Adafruit-bordje met STEMMA QT-connector. Meet lichtintensiteit. | D7: Nodig om de helderheid van de lamp (dimstappen) in lux te controleren. Zelfde BH1750-chip als de GY-302 uit je oorspronkelijke lijst; die is bij AZ-Delivery niet leverbaar ('Notify me when available'), dus dit is nu de hoofdkeuze. Bovendien kan hij samen met de AS7341 bij Kiwi besteld worden, wat aparte verzending bespaart. Ander I2C-adres dan de AS7341 (geen conflict). | E7: Koop hier | F7: 1 | G7: 0 | H7: 0 | I7: =IF(F7>G7,F7-G7+H7,0) -> 1 | J7: =ROUND(4.09*(1+Aannames!$B$4),2) -> 4.95 | K7: =I7*J7 -> 4.95 | L7: Kiwi Electronics | M7: 30+ stuks op voorraad (door de groep gecontroleerd op 2026-10-26). Kiwi toont € 4,09 excl. btw. | N7: Aangepast (GY-302 niet leverbaar) | O7: Geverifieerd | P7: Header-strip zit meestal los bij het bordje; de header pins van school kunnen ook gebruikt worden.
A8: R03 | B8: 1,3" IPS-TFT display 240x240 | C8: ST7789V3, SPI, 3,3 V. Toont kleur, hex/RGB en lux. | D8: De opdracht vraagt het resultaat op een klein display bij de ESP32, zodat er geen laptop nodig is. 1,3" met 240x240 pixels is goed leesbaar, werkt op 3,3 V en heeft SPI, dus snel genoeg en past bij de ESP32. | E8: Koop hier | F8: 1 | G8: 0 | H8: 0 | I8: =IF(F8>G8,F8-G8+H8,0) -> 1 | J8: 6.5 | K8: =I8*J8 -> 6.5 | L8: Tinytronics | M8: Direct leverbaar uit magazijn Eindhoven. | N8: Ja (in je lijst) | O8: Geverifieerd
A9: R04 | B9: LED 5 mm rood | C9: Statuslampje (meting bezig). | D9: Geeft in het donker zichtbaar aan dat een meting bezig is. Rood is goedkoop en valt weinig op in de kleurmeting, maar de LED is toch een lichtbron: afschermen van de sensoren. | E9: Koop hier | F9: 1 | G9: 0 | H9: 0 | I9: =IF(F9>G9,F9-G9+H9,0) -> 1 | J9: 0.17 | K9: =I9*J9 -> 0.17 | L9: Bits & Parts | M9: In assortiment; verzonden zelfde dag bij bestelling vóór 16:00. | N9: Ja (in je lijst) | O9: Geverifieerd
A10: R05 | B10: E27-fitting met snoer, schakelaar en stekker (zwart, 3,5 m) | C10: Kant-en-klaar lampsnoer met schakelaar en stekker om de lamp rechtstreeks te voeden. Zwart, 2 x 0,75 mm², max. 250 V, CE zichtbaar. | D10: Voedt de E27-lamp veilig vanaf het stopcontact. Kant-en-klaar en CE-gemarkeerd, zodat niemand zelf aan 230 V hoeft te werken. De schakelaar laat de lamp uit tijdens het opbouwen en de 3,5 m laat de stekker buiten de doos. Gekozen door de groep (bol.com-product). | E10: Koop hier | F10: 1 | G10: 0 | H10: 0 | I10: =IF(F10>G10,F10-G10+H10,0) -> 1 | J10: 19.99 | K10: =I10*J10 -> 19.99 | L10: bol.com (verkoper Prinos.nl) | M10: Levering uiterlijk 5 november; geen aparte verzendkosten. Stekkertype staat niet vermeld. | N10: Ja (in je lijst), aangepast | O10: Geverifieerd
A11: R06 | B11: Breadboard 830 punten (MB102) | C11: Steekbord voor het opbouwen van de schakeling. | D11: Hiermee bouw en wijzig je de schakeling zonder te solderen. 830 punten geeft plaats voor de 30-pin ESP32 én de modules. | E11: Koop hier | F11: 1 | G11: 0 | H11: 0 | I11: =IF(F11>G11,F11-G11+H11,0) -> 1 | J11: 3.95 | K11: =I11*J11 -> 3.95 | L11: Bits & Parts | M11: Op voorraad. In de winkelwagen: € 3,95 met 20% korting. | N11: Nieuw (ontbrak) | O11: Geverifieerd
A12: R07 | B12: Servo SG90 micro, 9 g | C12: Servomotortje om de Hue Motion Sensor te triggeren, 4,8-6 V, PWM. | D12: Beweegt een warm voorwerp of plaatje herhaald en op commando voor de bewegingssensor, zodat reactiesnelheid en betrouwbaarheid meetbaar zijn. Vervangt de DC-motor uit de originele lijst: een servo heeft een vaste positie, één PWM-draad en geen driver nodig. | E12: Koop hier | F12: 1 | G12: 0 | H12: 0 | I12: =IF(F12>G12,F12-G12+H12,0) -> 1 | J12: 4.25 | K12: =I12*J12 -> 4.25 | L12: Bits & Parts | M12: Direct uit voorraad (270 graden versie). | N12: Vervangt DC-motor | O12: Geverifieerd | P12: Enkel nodig voor de bewegingstest. Krijgen we de Hue Motion Sensor niet van school, dan laten we de servo achterwege en vervalt dit bedrag.
A13: B. Reeds in bezit of van school te krijgen, niet aangekocht
A14: R08 | B14: Philips Hue Bridge (v2) | C14: Hub voor Zigbee-lamp en -sensor. Incl. voeding en ethernetkabel. Biedt de lokale API voor de ESP32. | D14: Zonder Bridge werken de Zigbee-lamp en -bewegingssensor niet, en de ESP32 gebruikt de lokale API van de Bridge om de lamp te sturen. De v2 is het goedkoopst en volledig voldoende; de Pro is duurder zonder voordeel voor dit project. Er is een vrije LAN-poort op de router nodig. | E14: Koop hier | F14: 1 | G14: 1 | H14: 0 | I14: =IF(F14>G14,F14-G14+H14,0) -> 0 | J14: 59.99 | K14: =I14*J14 -> 0 | L14: Philips Hue (BE) | M14: Van school (verwacht). Referentie: Op voorraad bij Philips Hue BE. Bij Gamma 'bijna uitverkocht'. Gratis verzending vanaf € 50. | N14: Nieuw (ontbrak) | O14: Geverifieerd | P14: Naar verwachting krijgen we dit materiaal van school. Wordt dit uiteindelijk niet bevestigd, dan kopen we het alsnog: zet dan kolom G op 0, prijs en leverancier staan er al (zie ook het tabblad Alternatieven). Zonder Bridge is er niets te testen.
A15: R09 | B15: Philips Hue Motion Sensor (binnen) | C15: Zigbee-bewegingssensor, 2x AAA. Werkt enkel met een Hue Bridge. | D15: Dit is het toestel dat de servo moet triggeren: de test meet hoe snel en hoe betrouwbaar de sensor opnieuw afgaat. Het moet de originele Hue-sensor zijn omdat andere PIR-sensoren niet met de Bridge samenwerken. | E15: Koop hier | F15: 1 | G15: 1 | H15: 0 | I15: =IF(F15>G15,F15-G15+H15,0) -> 0 | J15: 44.99 | K15: =I15*J15 -> 0 | L15: Philips Hue (BE) | M15: Van school (verwacht). Referentie: Op voorraad bij Philips Hue BE. Gratis verzending vanaf € 50. | N15: Nieuw (ontbrak) | O15: Geverifieerd | P15: Naar verwachting krijgen we dit materiaal van school. Wordt dit uiteindelijk niet bevestigd, dan kopen we het alsnog: zet dan kolom G op 0, prijs en leverancier staan er al (zie ook het tabblad Alternatieven). Krijgen we de bewegingssensor niet, dan laten we de bewegingstest achterwege; dan vervallen ook de servo (R07), het warmtematje (R24) en de bijbehorende 3D-geprinte houders. De kleur- en luxtest van de lamp blijft ongewijzigd.
A16: R10 | B16: Philips Hue White and Color Ambiance E27 1100 lm | C16: Te testen kleurlamp, 16 miljoen kleuren, E27. | D16: Het te testen toestel: een kleurlamp is nodig om kleur en helderheid te verifiëren. Dit model heeft E27 en 1100 lm, de gangbare Hue-kleurlamp. Een goedkopere reservelamp staat bij Alternatieven. | E16: Koop hier | F16: 1 | G16: 1 | H16: 0 | I16: =IF(F16>G16,F16-G16+H16,0) -> 0 | J16: 54.95 | K16: =I16*J16 -> 0 | L16: Coolblue | M16: Van school (verwacht). Referentie: Besteld vóór 23:59, morgen gratis geleverd. Prijs € 54,95 uit Coolblue-lijst; controleer in de coolblue.be-winkelwagen. | N16: Ja (in je lijst) | O16: Geverifieerd | P16: Naar verwachting krijgen we dit materiaal van school. Wordt dit uiteindelijk niet bevestigd, dan kopen we het alsnog: zet dan kolom G op 0, prijs en leverancier staan er al (zie ook het tabblad Alternatieven). Zonder lamp is er niets te testen.
A17: R11 | B17: ESP32 DevKit V1, 30-pin | C17: Microcontroller met Wi-Fi, micro-USB, 3,3 V-logica. Draait MicroPython. | D17: Het brein van de testbank: leest de sensoren, stuurt display en servo aan en praat via Wi-Fi met de Hue Bridge. De DevKit V1 30-pin heeft 3,3 V-logica, MicroPython-ondersteuning en genoeg vrije pinnen. Al op school; de link verwijst naar de variant met losse (nog te solderen) pinnen. | E17: Koop hier | F17: 1 | G17: 1 | H17: 0 | I17: =IF(F17>G17,F17-G17+H17,0) -> 0 | J17: 11.55 | K17: =I17*J17 -> 0 | L17: Otronic | M17: Otronic: € 11,55 incl. btw, 42 stuks op voorraad; bestellingen vóór 14:00 op werkdagen gaan dezelfde dag weg. Pinnen worden los meegeleverd. De Otronic-verzending (€ 7,00 in de winkelwagen) vervalt, want de ESP32 komt van school. | N17: Ja (in je lijst) | O17: Geverifieerd | P17: Reeds beschikbaar op school (hergebruik); niet aangekocht. Is de school-ESP32 zonder gesoldeerde pinnen, dan moeten ze eerst gesoldeerd worden.
A18: R12 | B18: Drukknop 6x6 mm | C18: Wisselt tussen kleur- en luxweergave (GPIO27 naar GND, interne pull-up). | D18: Laat zonder laptop wisselen tussen kleur- en luxweergave. Met de interne pull-up van de ESP32 op GPIO27 is geen extra weerstand nodig. | E18: Koop hier | F18: 1 | G18: 1 | H18: 0 | I18: =IF(F18>G18,F18-G18+H18,0) -> 0 | J18: 0.15 | K18: =I18*J18 -> 0 | L18: Bits & Parts | M18: In assortiment; verzonden zelfde dag bij bestelling vóór 16:00. | N18: Ja (in je lijst) | O18: Geverifieerd | P18: Reeds beschikbaar op school (hergebruik); niet aangekocht.
A19: R13 | B19: Weerstand 330 Ohm, 1/4 W | C19: Stroombegrenzing voor de status-LED. | D19: Beperkt de stroom door de status-LED tot ongeveer 4 mA op 3,3 V, zodat LED en GPIO niet beschadigen. | E19: Koop hier | F19: 1 | G19: 1 | H19: 0 | I19: =IF(F19>G19,F19-G19+H19,0) -> 0 | J19: 0.1 | K19: =I19*J19 -> 0 | L19: Bits & Parts | M19: Direct uit voorraad. | N19: Ja (in je lijst) | O19: Geverifieerd | P19: Reeds beschikbaar op school (hergebruik); niet aangekocht.
A20: R14 | B20: Condensator 100 nF keramisch | C20: Ontkoppeling van de voedingsrail, dicht bij de modules plaatsen. | D20: Ontkoppelt de voedingsrail en vlakt snelle pieken af. Aantal 3: één bij de servo, één bij de ESP32 (3V3/GND) en één bij de sensoren. Keramisch, want snel en niet-gepolariseerd; de modules hebben zelf ook al condensatoren, dus dit is extra veiligheid. | E20: Koop hier | F20: 3 | G20: 3 | H20: 0 | I20: =IF(F20>G20,F20-G20+H20,0) -> 0 | J20: 0.2 | K20: =I20*J20 -> 0 | L20: Bits & Parts | M20: In assortiment. | N20: Ja (in je lijst) | O20: Geverifieerd | P20: Reeds beschikbaar op school (hergebruik); niet aangekocht. Keramisch 100 nF; controleer de waarde op het onderdeel.
A21: R15 | B21: Elco 1000 uF / 35 V | C21: Buffer tegen Wi-Fi- en servopieken. Vervangt 470 uF / 10 V (te krap op 5 V). Let op polariteit. | D21: Buffert pieken bij het starten van de servo en bij Wi-Fi-pieken, zodat de ESP32 niet reset (brown-out). 35 V geeft veel marge boven de 5 V-rail; 1000 µF is genoeg voor één SG90. Plaats hem op de 5 V-rail bij de servo. | E21: Koop hier | F21: 1 | G21: 1 | H21: 0 | I21: =IF(F21>G21,F21-G21+H21,0) -> 0 | J21: 0.35 | K21: =I21*J21 -> 0 | L21: Bits & Parts | M21: In assortiment. | N21: Aangepast (470 uF / 10 V) | O21: Geverifieerd | P21: Reeds beschikbaar op school (hergebruik); niet aangekocht. Let op: minstens 16 V en juiste polariteit (streep = min).
A22: R16 | B22: Voedingsadapter 5 V / 2 A micro-USB | C22: Voedt ESP32, display, sensoren en servo. Typische gsm-lader. | D22: Voedt de testbank zonder laptop. De servo trekt pieken, dus ruim stroom: een gsm-lader van 5 V met 1 A of meer volstaat. Hij wordt met de USB-kabel hieronder aan de ESP32 gehangen. | E22: Koop hier | F22: 1 | G22: 1 | H22: 0 | I22: =IF(F22>G22,F22-G22+H22,0) -> 0 | J22: 6.5 | K22: =I22*J22 -> 0 | L22: Tinytronics | M22: Direct leverbaar uit magazijn Eindhoven. | N22: Ja (in je lijst) | O22: Geverifieerd | P22: Reeds beschikbaar op school (hergebruik); niet aangekocht. Typische gsm-lader met USB-A (5 V, liefst 2 A); wordt gecombineerd met de USB-kabel.
A23: R17 | B23: Micro-USB datakabel 1 m | C23: USB-A naar Micro-B met data, om te programmeren (USB 2.0). | D23: Nodig om de ESP32 te programmeren (MicroPython) en daarna te voeden. Moet een datakabel zijn; kabels enkel voor laden werken niet. | E23: Koop hier | F23: 1 | G23: 1 | H23: 0 | I23: =IF(F23>G23,F23-G23+H23,0) -> 0 | J23: =ROUND(1.99*(1+Aannames!$B$4),2) -> 2.41 | K23: =I23*J23 -> 0 | L23: Kiwi Electronics | M23: 138 stuks op voorraad. Kiwi toont € 1,99 excl. btw. | N23: Ja (in je lijst) | O23: Geverifieerd | P23: Reeds beschikbaar op school (hergebruik); niet aangekocht. Moet een datakabel zijn (geen kabel enkel voor laden).
A24: R18 | B24: Jumperdraden male/male, 65 stuks | C24: Verbindingen op het breadboard. | D24: Verbindt de onderdelen op het breadboard en brengt de servo-stekker (female) naar het breadboard. Met ongebruikte, identieke draden zijn contacten betrouwbaar en is de kleurcodering eenduidig. | E24: Koop hier | F24: 1 | G24: 1 | H24: 0 | I24: =IF(F24>G24,F24-G24+H24,0) -> 0 | J24: 2.95 | K24: =I24*J24 -> 0 | L24: Bits & Parts | M24: Op voorraad. | N24: Nieuw (ontbrak) | O24: Geverifieerd | P24: Reeds in bezit. We gebruiken ongebruikte en identieke draden doorheen het hele project (betrouwbare contacten, eenduidige kleurcodering).
A25: R19 | B25: Dupont-kabels female/male 20 cm, 40 stuks | C25: Voor display, sensoren en servo. | D25: Verbindt modules met pinnen (display, sensoren) met het breadboard zonder te solderen. 20 cm laat toe de sensoren op afstand van de ESP32 te plaatsen. | E25: Koop hier | F25: 1 | G25: 1 | H25: 0 | I25: =IF(F25>G25,F25-G25+H25,0) -> 0 | J25: 1.85 | K25: =I25*J25 -> 0 | L25: Bits & Parts | M25: In assortiment. | N25: Nieuw (ontbrak) | O25: Geverifieerd | P25: Reeds in bezit.
A26: R20 | B26: Header pins male 1x40, 2,54 mm | C26: Voor ESP32 (indien zonder pinnen), BH1750, AS7341 en display (soldeerbout nodig). | D26: Pinnen worden aan modules gesoldeerd zodat ze in het breadboard of in Dupont-kabels passen. Bij de modules zitten meestal pinnen; de ESP32-variant van Otronic komt met losse pinnen. Op school aanwezig, dus niet aangekocht. | E26: Koop hier | F26: 1 | G26: 1 | H26: 0 | I26: =IF(F26>G26,F26-G26+H26,0) -> 0 | J26: 0.25 | K26: =I26*J26 -> 0 | L26: Bits & Parts | M26: Reeds op school aanwezig. | N26: Nieuw (ontbrak) | O26: Geverifieerd | P26: Reeds in bezit (school/groep); niet aangekocht. Soldeerbout en tin zijn ook op school.
A27: R21 | B27: Dubbelzijdige tape of hotglue | C27: Sensoren, display en servo bevestigen waar geen 3D-geprint onderdeel voor is. | D27: Voor het vastzetten van wat niet geprint wordt (kabels, doos). Een stabiele bevestiging houdt afstand en hoek tot de lamp constant, en dat bepaalt de meetnauwkeurigheid. | E27: Geen link: lokaal kopen (bv. hobbywinkel) | F27: 1 | G27: 1 | H27: 0 | I27: =IF(F27>G27,F27-G27+H27,0) -> 0 | J27: 3 | K27: =I27*J27 -> 0 | L27: Hobbywinkel (afhalen) | M27: Reeds in bezit. | N27: Ja (in je lijst) | O27: Schatting | P27: Reeds in bezit (school/groep); niet aangekocht.
A28: R22 | B28: Zwart karton, vilt of verf (doos) | C28: Donkere meetopstelling: de testmodule komt in een grote kartonnen doos (of vergelijkbaar). Binnenzijde zwart maken. | D28: Lichtmetingen vragen een donkere ruimte zonder reflecties. Een grote kartonnen doos is goedkoop en makkelijk aan te passen; zwart binnenin vermindert omgevingslicht en terugkaatsing. | E28: Geen link: lokaal kopen (bv. hobbywinkel) | F28: 1 | G28: 1 | H28: 0 | I28: =IF(F28>G28,F28-G28+H28,0) -> 0 | J28: 4 | K28: =I28*J28 -> 0 | L28: Hobbywinkel (afhalen) | M28: Reeds in bezit. | N28: Ja (in je lijst) | O28: Schatting | P28: Reeds in bezit (school/groep); niet aangekocht. Een bestaande doos wordt hergebruikt; kies een doos die groot genoeg is voor lamp, sensoren en de Hue Motion Sensor, en zorg voor luchtopening of ventilatie omdat de lamp en een eventueel warmtematje de doos opwarmen.
A29: R23 | B29: 3D-geprinte onderdelen (op maat) | C29: Kleine hardwaredelen worden custom 3D-geprint: houders voor AS7341 en BH1750, display, servo- en sensorsteun, servoarm voor het plaatje. | D29: Met eigen ontwerpen liggen afstand en hoek tussen lamp en sensor vast en zijn metingen herhaalbaar, wat met tape niet lukt. Kosten zijn enkel het filament (PLA, schatting ongeveer € 2 incl. mislukte prints); de printer is van school of de groep. | E29: Geen link: zelf printen (eigen ontwerp/STL) | F29: 1 | G29: 1 | H29: 0 | I29: =IF(F29>G29,F29-G29+H29,0) -> 0 | J29: 2 | K29: =I29*J29 -> 0 | L29: School / eigen 3D-printer | M29: Printer en filament zijn beschikbaar. | N29: Nieuw (op verzoek) | O29: Schatting | P29: Reeds in bezit (school/groep); niet aangekocht. Enkel de ontwerpen moeten nog gemaakt worden. Meet de modules op vóór het ontwerp en print eerst een testexemplaar.
A30: R24 | B30: Warmtematje (optioneel) of handwarmer als warmtebron | C30: Warmtebron om de PIR-sensor te triggeren: het warmtematje dat de groep al heeft. Alternatief: een herbruikbare handwarmer op de servoarm. | D30: Een PIR-sensor reageert op warmteverschil en niet op een voorwerp dat even warm is als de omgeving. Daarom een warmtebron als trigger; een handwarmer is goedkoop en herbruikbaar. | E30: Geen link: warmtematje reeds in bezit | F30: 1 | G30: 1 | H30: 0 | I30: =IF(F30>G30,F30-G30+H30,0) -> 0 | J30: 5 | K30: =I30*J30 -> 0 | L30: Hobbywinkel (afhalen) | M30: Reeds in bezit (warmtematje). Handwarmer alleen kopen als het matje niet werkt. | N30: Nieuw (ontbrak) | O30: Schatting | P30: Een PIR-sensor reageert op warmteverschil en werkt mogelijk niet met een voorwerp dat dezelfde temperatuur heeft als de omgeving. Daarom kan de student een warmtematje gebruiken om de sensor te triggeren: het matje ligt vast achter het pad van de servo en de servo beweegt een plaatje ervoor langs. Optioneel: werkt de sensor al met alleen het plaatje, dan is het matje niet nodig. Krijgen we de bewegingssensor niet, dan vervalt het matje samen met de servo. Prijs is een schatting van de vervangwaarde.
J32: Onderdelen incl. btw | K32: =SUM(K6:K30) -> 58.31
J33: Verzendkosten incl. btw | K33: =Leveranciers!F11 -> 21.41
J34: TOTAAL incl. btw | K34: =K32+K33 -> 79.72
J35: TOTAAL excl. btw | K35: =K34/(1+Aannames!$B$4) -> 65.884298
J36: Btw (21%) | K36: =K34-K35 -> 13.835702
J37: Waarvan geschatte prijzen | K37: =SUMIFS(BOM!$K$6:$K$30,BOM!$O$6:$O$30,"Schatting") -> 0
J38: Waarde reeds in bezit (school, zonder Hue) | K38: =SUMPRODUCT(G17:G30,J17:J30) -> 40.71
J39: Waarde Hue-materiaal (verwacht van school) | K39: =SUMPRODUCT(G14:G16,J14:J16) -> 159.93
J40: Meerprijs als Hue-materiaal toch niet van school komt | K40: =F14*J14+F15*J15+F16*J16 -> 159.93
J42: Controle: som leveranciers = onderdelen | K42: =Leveranciers!B13 -> OK
A45: C. Alternatieven voor de licht- en kleursensor (NIET meegeteld in het totaal)
...

Sheet Leveranciers
A1: Verzending per leverancier
A2: Verzending wordt per leverancier berekend: gratis vanaf de drempel, anders het tarief. Gele cellen zijn aanpasbaar. Alleen te kopen onderdelen tellen mee.
A4: Leverancier | B4: Subtotaal incl. btw | C4: Gratis vanaf (€) | D4: Tarief onder drempel (€) | E4: Status tarief | F4: Verzendkosten | G4: Totaal incl. verzending | H4: Opmerking
A5: Philips Hue (BE) | B5: =SUMIFS(BOM!$K$6:$K$30,BOM!$L$6:$L$30,A5) -> 0 | C5: 50 | D5: 4.95 | E5: Drempel geverifieerd, tarief geschat | F5: =IF(B5=0,0,IF(B5>=C5,0,D5)) -> 0 | G5: =B5+F5 -> 0 | H5: Gratis verzending vanaf € 50.
A6: Coolblue | B6: =SUMIFS(BOM!$K$6:$K$30,BOM!$L$6:$L$30,A6) -> 0 | C6: 0 | D6: 0 | E6: Geverifieerd | F6: =IF(B6=0,0,IF(B6>=C6,0,D6)) -> 0 | G6: =B6+F6 -> 0 | H6: Gratis levering volgens de productpagina.
A7: Kiwi Electronics | B7: =SUMIFS(BOM!$K$6:$K$30,BOM!$L$6:$L$30,A7) -> 23.45 | C7: 100 | D7: 6.64 | E7: Geverifieerd in winkelwagen (groep, 26 okt) | F7: =IF(B7=0,0,IF(B7>=C7,0,D7)) -> 6.64 | G7: =B7+F7 -> 30.09 | H7: Eén verzending voor alle Kiwi-artikelen (AS7341 en BH1750). Gratis naar België vanaf € 100.
A8: Tinytronics | B8: =SUMIFS(BOM!$K$6:$K$30,BOM!$L$6:$L$30,A8) -> 6.5 | C8: 50 | D8: 8.82 | E8: Geverifieerd in winkelwagen (groep, 26 okt); drempel niet gevonden | F8: =IF(B8=0,0,IF(B8>=C8,0,D8)) -> 8.82 | G8: =B8+F8 -> 15.32 | H8: PostNL pakket: € 7,29 excl. btw = € 8,82 incl. btw (totaal winkelwagen € 15,32). Hoger dan de prijs van het display (€ 6,50); subtotaal ligt onder elke gangbare drempel.
A9: Bits & Parts | B9: =SUMIFS(BOM!$K$6:$K$30,BOM!$L$6:$L$30,A9) -> 8.37 | C9: 80 | D9: 5.95 | E9: Geverifieerd in winkelwagen (groep, 26 okt) | F9: =IF(B9=0,0,IF(B9>=C9,0,D9)) -> 5.95 | G9: =B9+F9 -> 14.32 | H9: Gratis vanaf € 80 (pakketartikelen).
A10: bol.com (verkoper Prinos.nl) | B10: =SUMIFS(BOM!$K$6:$K$30,BOM!$L$6:$L$30,A10) -> 19.99 | C10: 0 | D10: 0 | E10: Geverifieerd: geen aparte verzendkosten | F10: =IF(B10=0,0,IF(B10>=C10,0,D10)) -> 0 | G10: =B10+F10 -> 19.99 | H10: Geen aparte verzendkosten (aanbieding vermeldt 'inclusief verzendkosten'; bevestigd door de groep).
A11: TOTAAL | B11: =SUM(B5:B10) -> 58.31 | F11: =SUM(F5:F10) -> 21.41 | G11: =SUM(G5:G10) -> 79.72
A13: Controle: alle BOM-leveranciers staan in deze lijst | B13: =IF(ROUND(B11-SUM(BOM!K6:K30),2)=0,"OK","FOUT: leverancier ontbreekt") -> OK
A15: Tip: minder verzending betalen kan door onderdelen bij één shop te bundelen en de totaalprijs te vergelijken.

Sheet Alternatieven
A1: Alternatieven bij dure of kritieke onderdelen
A2: Verschil = prijs alternatief min gekozen onderdeel. Blauwe prijzen zijn ingevoerd, zwarte komen uit de BOM. Alternatieven voor de licht- en kleursensor staan onderaan het tabblad BOM.
A4: Onderdeel in BOM | B4: Alternatief | C4: Link | D4: Prijs incl. btw | E4: Verschil met BOM | F4: Voordelen | G4: Nadelen / risico | H4: Advies
A5: =BOM!B14 -> Philips Hue Bridge (v2) | B5: Hue Bridge bij Gamma.be | C5: Bekijk | D5: 69.99 | E5: =IF(ISNUMBER(D5),D5-BOM!J14,"n.v.t.") -> 10 | F5: Zelfde Bridge v2; € 10 duurder maar afhalen of thuis leveren in België. | G5: Online 'bijna uitverkocht'. | H5: Alleen als Philips uitverkocht is
A6: =BOM!B14 -> Philips Hue Bridge (v2) | B6: Hue Bridge Pro | C6: Bekijk | D6: 149.99 | E6: =IF(ISNUMBER(D6),D6-BOM!J14,"n.v.t.") -> 90 | F6: Meer apparaten, MotionAware en SpatialAware; beter beschikbaar. | G6: Prijs steeg in 2026 van € 99,99 naar circa € 149,99 (adviesprijs). Voor dit project niet nodig. | H6: Niet nodig
A7: =BOM!B14 -> Philips Hue Bridge (v2) | B7: Starterpack 2x E27 + Bridge Pro (Coolblue, € 135) | C7: Bekijk | D7: 135 | E7: =IF(ISNUMBER(D7),D7-BOM!J14,"n.v.t.") -> 75.01 | F7: Eén bestelling, twee lampen (één reserve). Vergelijk met Bridge v2 + 1 lamp = € 114,94. | G7: Bridge Pro i.p.v. v2; Motion Sensor nog apart. | H7: Alleen bij reservelamp
A8: =BOM!B15 -> Philips Hue Motion Sensor (binnen) | B8: Hue Motion Sensor bij BCC.nl | C8: Bekijk | D8: 39.99 | E8: =IF(ISNUMBER(D8),D8-BOM!J15,"n.v.t.") -> -5 | F8: € 5 goedkoper dan Philips BE; gratis verzending. | G8: Nederlandse shop, levering naar België niet bevestigd. | H8: Check levering naar BE
A9: =BOM!B15 -> Philips Hue Motion Sensor (binnen) | B9: Hue Motion Sensor bij Gamma.nl | C9: Bekijk | D9: 38.49 | E9: =IF(ISNUMBER(D9),D9-BOM!J15,"n.v.t.") -> -6.5 | F9: Goedkoopste gevonden. | G9: Nederlandse shop, € 4,95 verzending, levering naar België niet bevestigd. | H9: Check levering naar BE
A10: =BOM!B16 -> Philips Hue White and Color Ambiance E27 1100 lm | B10: Hue Essential White and Color E27 (2-pack € 34,95, Hornbach NL) | C10: Bekijk | D10: 17.48 | E10: =IF(ISNUMBER(D10),D10-BOM!J16,"n.v.t.") -> -37.47 | F10: Veel goedkoper; goed als reservelamp of voor testen van de opstelling. | G10: Lagere lichtopbrengst (806 lm); niet de lamp die Brightsense test. Niet reserveerbaar online. | H10: Alleen voor ontwikkeling
A11: =BOM!B16 -> Philips Hue White and Color Ambiance E27 1100 lm | B11: Hue White and Color E27 bij Hubo.be | C11: Bekijk | D11: 64.99 | E11: =IF(ISNUMBER(D11),D11-BOM!J16,"n.v.t.") -> 10.04 | F11: Belgische shop. | G11: € 10 duurder; levering binnen 2 weken. | H11: Niet nodig
A12: =BOM!B10 -> E27-fitting met snoer, schakelaar en stekker (zwart, 3,5 m) | B12: Kopp Euro-aansluitsnoer met schakelaar en lamphouder E27, wit (2 m, Praxis.nl) | C12: Bekijk | D12: 10.7 | E12: =IF(ISNUMBER(D12),D12-BOM!J10,"n.v.t.") -> -9.29 | F12: Goedkoper, merkproduct van Kopp. | G12: Nederlandse shop, levering naar België en verzendkosten niet bevestigd; snoer korter (2 m); prijs niet opnieuw gecontroleerd. | H12: Reserveoptie
A13: =BOM!B6 -> AS7341 kleur-/spectraalsensor | B13: Adafruit AS7341 rechtstreeks (US$ 18,95) | C13: Bekijk | D13: zie link | E13: =IF(ISNUMBER(D13),D13-BOM!J6,"n.v.t.") -> n.v.t. | F13: Bronshop; prijs in dollar (+ invoer en verzending). | G13: Meldt 'out of stock'; levering naar EU duurder. | H13: Reserveoptie
A14: =BOM!B6 -> AS7341 kleur-/spectraalsensor | B14: AS7341 bij Pimoroni (UK) | C14: Bekijk | D14: zie link | E14: =IF(ISNUMBER(D14),D14-BOM!J6,"n.v.t.") -> n.v.t. | F14: Zelfde Adafruit-board. | G14: Prijs niet gecontroleerd; UK-import (douane/btw). | H14: Reserveoptie
A15: =BOM!B6 -> AS7341 kleur-/spectraalsensor | B15: AS7341 bij The Pi Hut (UK) | C15: Bekijk | D15: zie link | E15: =IF(ISNUMBER(D15),D15-BOM!J6,"n.v.t.") -> n.v.t. | F15: Zelfde Adafruit-board. | G15: Prijs niet gecontroleerd; UK-import (douane/btw). | H15: Reserveoptie

Sheet Compatibiliteit
A1: Controle: compatibiliteit en ontbrekende onderdelen
A2: Gecontroleerd op papier (datasheets en productpagina's), niet op een echte opstelling. OK = geen probleem verwacht; Let op = beslissing of test nodig. GPIO-nummers zijn voorstellen.
A4: Controle | B4: Onderdelen | C4: Resultaat | D4: Toelichting en aanpak
A5: Logicaniveau en voeding | B5: ESP32, AS7341, BH1750, display | C5: OK | D5: ESP32 werkt op 3,3 V. AS7341-breakout en BH1750-bordje accepteren 3-5 V, het ST7789-display werkt op 3,3 V. Voed sensoren en display vanaf 3V3, niet vanaf 5 V.
A6: I2C-adressen | B6: AS7341 (0x39), BH1750 (0x23) | C6: OK | D6: Geen conflict. Beide aan SDA/SCL van de ESP32 (standaard GPIO21 en GPIO22). Beide bordjes hebben pull-ups; twee in parallel is geen probleem.
A7: SPI-display | B7: ESP32, ST7789 (7 pinnen, zonder CS) | C7: OK | D7: SPI op eigen pinnen (bv. SCK GPIO18, MOSI GPIO23), los van I2C. Zet CS niet als pin; reset, DC en backlight op vrije GPIO.
A8: Servo en voeding | B8: SG90, elco, 100 nF, adapter | C8: Let op | D8: SG90 heeft 4,8-6 V nodig: voed hem vanaf VIN (5 V), niet vanaf 3V3, met gemeenschappelijke massa. Het signaal van 3,3 V werkt meestal. Bij blokkeren pikt de servo hoger: adapter van minstens 1 A, elco van 1000 µF bij de servo en 100 nF als extra.
A9: Voeding via USB | B9: Gsm-lader, USB-kabel, ESP32 | C9: OK | D9: De ESP32 krijgt 5 V via micro-USB; VIN levert dan ongeveer 5 V voor de servo. De kabel moet een datakabel zijn om te programmeren.
A10: Knop en LED | B10: Drukknop, LED, 330 Ω | C10: OK | D10: Knop op GPIO27 met interne pull-up. LED op een vrije GPIO via 330 Ω (ongeveer 4 mA). Vermijd GPIO 34-39 als uitgang en opstartpinnen (0, 2, 12, 15).
A11: Hue-systeem | B11: Bridge, Motion Sensor, lamp | C11: Let op | D11: Zigbee-lamp en -sensor werken samen met de Bridge v2. Deze onderdelen krijgen we naar verwachting van school; vraag tijdig na welk model van Bridge (v2 of Pro) en welke lamp het is. De Bridge heeft een vrije LAN-poort en stroom nodig, en de ESP32 moet via Wi-Fi (2,4 GHz) op hetzelfde netwerk zitten. Schoolnetwerken hebben soms client-isolatie of een aparte login: test dit vooraf. Noodoplossing is een eigen kleine router of hotspot (niet in de BOM).
A12: Motion Sensor | B12: Hue Motion Sensor, servo, warmtebron | C12: Let op | D12: Een PIR reageert op warmteverschil. Gebruik een warmtebron of warmtematje, zie de opmerking bij de warmtebron. Test in de doos of de sensor zonder omgevingsbeweging nog triggert; de lamp en het matje warmen de doos op. De sensor werkt op 2 AAA-batterijen (zouden meegeleverd zijn; controleer bij ontvangst).
A13: Netspanning en doos | B13: Lamp, lampsnoer, kartonnen doos | C13: Let op | D13: Lamp van ongeveer 10 W op een snoer van 2 x 0,75 mm² is prima. Houd het snoer met trekontlasting in de doos, laat de stekker erbuiten en zorg voor luchtopening. Controleer het stekkertype. Niet zelf aan 230 V wiren.
A14: Lichtmeting | B14: AS7341, BH1750, display, LED, lamp | C14: Let op | D14: De AS7341 kan verzadigen op een lamp van 1100 lm: werk met afstand, een diffusor en integratietijd. Het display (backlight) en de status-LED zijn lichtbronnen die de meting verstoren: schakel de backlight tijdens de meting uit of schaduw de sensoren af. Alles zwart binnenin.
A15: Mechanisch | B15: ESP32, breadboard, pinnen, kabels | C15: OK | D15: De 30-pin ESP32 past op een breadboard met 830 punten. De servo-stekker is female: gebruik male/male jumpers naar het breadboard en Dupont F/M voor display en sensoren. De ESP32 van Otronic (en eventueel de modules) komt met losse pinnen: solderen.
... A17: Mogelijk vergeten | B17: Gereedschap en netwerk (niet in de BOM) | C17: Let op | D17: Soldeerbout met tin, kniptang en een kleine schroevendraaier (school). Een vrije poort op een router voor de Bridge. Een computer met MicroPython-tools om te flashen. Een stopcontact in de buurt van de doos. Geen van deze is in de prijs opgenomen.

Sheet Wijzigingen
A1: Wijzigingen ten opzichte van je oorspronkelijke onderdelenlijst
A3: Origineel | B3: Probleem | C3: Oplossing in de BOM
A4: DC Motor (bewegingstest) | B4: Een DC-motor draait door en heeft een driver nodig; hij kan een sensor niet herhaald en op een vaste plek triggeren. | C4: Vervangen door SG90-servo (R07) + buffercondensator (R15). Servo op 5 V (VIN), signaal via een GPIO, massa gemeenschappelijk.
A5: (ontbrak) Hue Bridge | B5: Zigbee-lamp en Motion Sensor werken enkel via een Bridge; de ESP32 spreekt de Bridge aan via de lokale API. | C5: Toegevoegd (R08). Er is een vrije LAN-poort nodig.
A6: (ontbrak) Hue Motion Sensor | B6: De bewegingssensor die getest moet worden stond niet op de lijst. | C6: Toegevoegd (R09).
A7: Servo triggert PIR | B7: Een PIR reageert op bewegende warmte, niet op een bewegend stuk karton. | C7: Warmtematje (R24) dat vastligt terwijl de servo een plaatje ervoor langs beweegt, of een handwarmer op de servoarm; afstand en snelheid testen.
A8: (ontbrak) Breadboard, jumpers, headers | B8: Zonder deze onderdelen kan niets worden aangesloten. | C8: Toegevoegd (R06, R18, R19, R20). Jumpers, Dupont en header pins zijn al in bezit.
A9: Condensator 470 uF / 10 V | B9: 10 V laat weinig marge op een 5 V-rail. | C9: Vervangen door 1000 uF / 35 V (R15). Let op polariteit.
A10: 5 V USB-voedingsadapter + micro-USB datakabel | B10: De voedingsadapter heeft meestal een vaste kabel (alleen voeding). | C10: Gsm-lader (R16) + aparte datakabel (R17), beide al op school.
A11: E27-lampsnoer | B11: Moet kant-en-klaar zijn (netspanning). | C11: R05: bol.com-snoer van 3,5 m met schakelaar en stekker, niet zelf wiren.
A12: ESP32 op school | B12: De ESP32 moet niet aangekocht worden. | C12: R11 staat als hergebruik; de link verwijst naar Otronic (variant met losse pinnen, € 11,55) als referentie en voor de waarde.
A13: GY-302 (BH1750) | B13: Niet leverbaar bij AZ-Delivery op 2026-10-26. | C13: Vervangen door de Adafruit BH1750 bij Kiwi (R02): zelfde chip, op voorraad en samen met de AS7341 besteld (één verzending). De GY-302 staat bij de alternatieven.
A14: Meetopstelling | B14: AS7341 kan verzadigen op een lamp van 1100 lm op korte afstand. | C14: Geen extra onderdeel: werk met afstand, diffusor (karton) en integratietijd.
... A16: Kleine hardwaredelen | B16: Houders voor sensoren, display en servo moeten stevig en herhaalbaar zijn. | C16: Custom 3D-print (R23) met de printer van school of de groep; geen aankoop.

Sheet Aannames
A1: Aannames en bronnen
A3: Parameter | B3: Waarde | C3: Toelichting
A4: BTW-tarief | B4: 0.21 | C4: Belgisch tarief 21%. Prijzen zijn consumentenprijzen incl. btw; excl. btw = prijs / (1 + tarief). Kiwi Electronics toont prijzen excl. btw: die zijn hier omgerekend met dit tarief.
A5: Controledatum prijzen en voorraad | B5: 2026-10-26 | C5: Prijzen en voorraad nagekeken in webwinkels op deze datum. Philips Hue verhoogde in 2026 meermaals de prijzen: controleer vóór bestelling opnieuw.
A6: Valuta | B6: EUR | C6: Alle bedragen in euro.
A8: Opmerkingen
A9: Prijsstatus 'Geverifieerd' = prijs gezien op de productpagina of in de zoekresultaten van de shop op de controledatum. 'Schatting' (oranje) = prijs niet bevestigd; controleer in de winkelwagen.
A10: Verzendkosten per leverancier (tabblad Leveranciers), door de groep gecontroleerd in de winkelwagen op 2026-10-26: Kiwi € 6,64 voor alle Kiwi-artikelen samen, Bits & Parts € 5,95, Tinytronics € 8,82 (€ 7,29 excl. btw). Bij bol.com zijn er geen aparte verzendkosten. Philips Hue (gratis vanaf € 50) en Coolblue (gratis) zijn alleen relevant als het Hue-materiaal toch gekocht moet worden.
A11: Beschikbaarheid: de GY-302 bij AZ-Delivery was op 2026-10-26 niet leverbaar; daarom is de Adafruit BH1750 bij Kiwi (30+ stuks op voorraad) de hoofdkeuze geworden.
A12: Hergebruik: ESP32, weerstand, condensatoren, voedingsadapter (gsm-lader), USB-kabel, drukknop, jumperdraden, Dupont-kabels, header pins, tape/lijm, kartonnen doos, warmtematje en de 3D-printer met filament zijn al beschikbaar (deel B van de BOM, kolom G = aantal nodig, dus niets te kopen). De Hue Bridge, Motion Sensor en lamp krijgen we naar verwachting van school (deel B). Is dat niet bevestigd, dan kopen we ze alsnog: zet kolom G op 0; de meerprijs staat onder de totalen (verzending blijft € 0: Philips Hue en Coolblue leveren gratis boven hun drempel).
A13: Reserve: er wordt bewust geen reserve besteld. Kolom H (Reserve) staat overal op 0 en kan later aangepast worden; het aantal te kopen en het totaal passen zich automatisch aan.
A14: De Hue Motion Sensor wordt volgens de fabrikant met 2 AAA-batterijen geleverd, de Hue Bridge met voeding en ethernetkabel. Controleer dit bij ontvangst.
A15: Veiligheid: koop de E27-fitting met snoer en stekker kant-en-klaar. Zelf aan 230 V wiren niet doen zonder begeleiding.
A16: Scenario zonder bewegingssensor: krijgen we de Hue Motion Sensor niet van school, dan laten we de bewegingstest achterwege en vervallen de servo (€ 4,25), het warmtematje en de bijbehorende 3D-geprinte houders. De kleur- en luxtest van de lamp blijft.
A17: Opstelling: de testmodule staat in een grote kartonnen doos (donkere meetruimte). Controleer of de PIR-sensor in de doos nog goed triggert en of de Zigbee-verbinding stabiel blijft.
A18: Kleine hardwaredelen worden custom 3D-geprint met de printer en het filament van school of de groep; er is geen aankoop. De bedragen van doos, tape, warmtematje en print in deel B zijn schattingen van de vervangwaarde (oranje).
A19: De alternatieven voor de licht- en kleursensor staan onderaan het tabblad BOM en tellen niet mee in het totaal.
A20: Legenda: blauwe tekst = ingevoerde waarde, gele cel = zelf aan te passen, oranje cel = geschatte prijs, zwarte tekst = formule.
